### 15-1. 예외상황과 예외처리의 이해

#### 예외처리를 하지 않았을 때
```C++
#include <iostream>
using namespace std;

int main(void)
{
	int num1, num2;
	cout << "두 개의 숫자 입력: ";
	cin >> num1 >> num2;

	cout << "나눗셈의 몫: " << num1 / num2 << endl;
	cout << "나눗셈의 나머지: " << num1 % num2 << endl;
	return 0;
}
```

#### if문을 이용한 예외의 처리
- 단점 : 예외처리를 위한 코드와 프로그램의 흐름을 구성하는 코드를 쉽게 구분하지 못한다.
```C++
#include <iostream>
using namespace std;

int main(void)
{
	int num1, num2;
	cout << "두 개의 숫자 입력: ";
	cin >> num1 >> num2;

	if (num2 == 0)
	{
		cout << "제수는 0이 될 수 없습니다." << endl;
		cout << "프로그램을 다시 실행하세요." << endl;
	}
	else
	{
		cout << "나눗셈의 몫: " << num1 / num2 << endl;
		cout << "나눗셈의 나머지: " << num1 % num2 << endl;
	}
	
	return 0;
}
```

### 15-2. 예외상황과 예외처리의 이해
- try : 예외 발생에 대한 검사의 범위를 지정 
- catch : 예외처리 코드의 삽입
- throw : 예외가 발생했음을 알리는 문장의 구상에 사용

try 다음에 catch가 나오며, try 블록에서 발생한 예외는 catch 블록에서 처리됨.

```C++
#include <iostream>
using namespace std;

int main(void)
{
	int num1, num2;
	cout << "두 개의 숫자 입력: ";
	cin >> num1 >> num2;

	try
	{
		if (num2 == 0)
			throw num2;
		cout << "나눗셈의 몫: " << num1 / num2 << endl;
		cout << "나눗셈의 나머지: " << num1 % num2 << endl;
	}
	catch(int expn)  //예외가 발생하면 num2의 값으로 expn이 초기화됨
	{
		cout << "제수는 0이 될 수 없습니다." << endl;
		cout << "프로그램을 다시 실행하세요." << endl;
	}
	
	cout << "end of main" << endl;
	
	return 0;
}
```
- try 블록을 만나면 그 안에 삽입된 문장이 순서대로 실행됨
- try 블록 내에서 예외가 발생하지 않으면 catch 블록 이후를 실행함
- try 블록 내에서 예외가 발생하면, 예외가 발생한 지점 이후의 나머지 try 영역을 건너


### 15-3. Stack Unwinding(스택 풀기)
- 함수에서 throw 절에 의해 예외가 발생했는데 처리하지 않았을 때는
<br> 예외처리에 대한 책음은 함수를 호출한 영역으로 넘어감!!

- 함수 내에서 함수를 호출한 영역으로 예외 데이터를 전달하면, 해당 함수는 더 이상 실행되지 않고 종료됨.

```c++
#include <iostream>
using namespace std;

void Divide(int num1, int num2)
{
	if (num2 == 0)
		throw num2;
	cout << "나눗셈의 몫: " << num1 / num2 << endl;
	cout << "나눗셈의 나머지: " << num1 % num2 << endl;
}

int main(void)
{
	int num1, num2;
	cout << "두 개의 숫자 입력: ";
	cin >> num1 >> num2;

	try
	{
		Divide(num1, num2);
		cout << "나눗셈을 마쳤습니다." << endl;
	}
	catch(int expn)  //예외가 발생하면 num2의 값으로 expn이 초기화됨
	{
		cout << "제수는 " << expn << "이 될 수 없습니다." << endl;
		cout << "프로그램을 다시 실행하세요." << endl;
	}
	
	return 0;
}
```

#### 예외상황이 발생한 위치와 예외상황을 처리해야 하는 위치가 다른 경우
```C++
#include <iostream>
#include <cstring>
#include <cmath>
using namespace std;

int StoI(char * str)
{
	int len = strlen(str);
	int num = 0;
	for (int i = 0; i < len; i++)
	{
		if (str[i]<'0' || str[i]>'9')
			throw str[i];
		num += (int)(pow((double)10, (len - 1) - i)*(str[i] + (7 - '7')));
	}
	return num;
}

int main(void)
{
	char str1[100];
	char str2[200];

	while (1)
	{
		cout << "두 개의 숫자 입력: ";
		cin >> str1 >> str2;

		try
		{
			cout << str1 << " + " << str2 << " = " << StoI(str1) + StoI(str2) << endl;
			break;
		}
		catch (char ch)
		{
			cout << "문자 " << ch << "가 입력되었습니다." << endl;
			cout << "재입력 진행합니다." << endl << endl;
		}
	}
	cout << "프로그램을 종료합니다." << endl;
	return 0;
}
```

#### 스택 풀기(Stack Unwinding)
- 예외가 처리되지 않아서 함수를 호출한 영역으로 예외 데이터가 전달되는 현상

```C++
#include <iostream>
using namespace std;

void SimpleFuncOne(void);
void SimpleFuncTwo(void);
void SimpleFuncThree(void);

int main(void)
{
	try
	{
		SimpleFuncOne();
	}
	catch(int expn)
	{
		cout << "예외코드: " << expn << endl;
	}
	return 0;
}

void SimpleFuncOne(void)
{
	cout << "SimpleFuncOne(void)" << endl;
	SimpleFuncTwo();
}

void SimpleFuncTwo(void)
{
	cout << "SimpleFuncTwo(void)" << endl;
	SimpleFuncThree();
}

void SimpleFuncThree(void)
{
	cout << "SimpleFuncThree(void)" << endl;
	throw - 1;
}
```

#### 하나의 try 블록과 다수의 catch 블록
```C++
#include <iostream>
#include <cstring>
#include <cmath>
using namespace std;

int StoI(char * str)
{
	int len = strlen(str);
	int num = 0;

	if (len != 0 && str[0] == '0')
		throw 0;

	for (int i = 0; i < len; i++)
	{
		if (str[i]<'0' || str[i]>'9')
			throw str[i];
		num += (int)(pow((double)10, (len - 1) - i)*(str[i] + (7 - '7')));
	}
	return num;
}

int main(void)
{
	char str1[100];
	char str2[200];

	while (1)
	{
		cout << "두 개의 숫자 입력: ";
		cin >> str1 >> str2;

		try
		{
			cout << str1 << " + " << str2 << " = " << StoI(str1) + StoI(str2) << endl;
			break;
		}
		catch (char ch)
		{
			cout << "문자 " << ch << "가 입력되었습니다." << endl;
			cout << "재입력 진행합니다." << endl << endl;
		}
		catch (int expn)
		{
			if (expn == 0)
				cout << "0으로 시작하는 숫자는 입력불가." << endl;
			else
				cout << "비정상적 입력이 이루어졌습니다." << endl;

			cout << "재입력 진행합니다." << endl << endl;
		}
	}
	cout << "프로그램을 종료합니다." << endl;
	return 0;
}
```

#### 전달되는 예외의 명시
`int ThrowFunc(int num) throw(int, char)`
- 만약 int와 char이외의 걸 예외데이터로 전달하면 프로그램 종료!

### 15-4. 예외상황을 표현하는 예외 클래스의 설계
- 예외 객체 : 예외발생을 알리는데 사용되는 객체
- 예외 클래스 : 예외객체의 생성을 위해 정의된 클래스
```C++
#include <iostream>
#include <cstring>
using namespace std;

class DepositException
{
private:
	int reqDep; // 요청 입금액
public:
	DepositException(int money):reqDep(money)
	{}
	void ShowExceptionReason()
	{
		cout << "[예외 메시지: " << reqDep << "는 입금불가]" << endl;
	}
};

class WithdrawExcption
{
private:
	int balance; //잔고
public:
	WithdrawExcption(int money):balance(money)
	{}
	void ShowExceptionReason()
	{
		cout << "[예외 메시지: 잔액 " << balance << ", 잔액부족]" << endl;
	}
};

class Account
{
private:
	char accNum[50]; // 계좌번호
	int balance; //잔고
public:
	Account(const char * acc, int money) :balance(money)
	{
		strcpy(accNum, acc);
	}
	void Deposit(int money) throw (DepositException)
	{
		if (money < 0)
		{
			DepositException expn(money);
			throw expn;
		} 
		balance += money;
	}
	void Withdraw(int money) throw (WithdrawExcption)
	{
		if (money > balance)
			throw WithdrawExcption(balance);  // 예외객체를 전달하는 일반적인 방법
		balance -= money;
	}
	void ShowMyMoney()
	{
		cout << "잔고: " << balance << endl << endl;
	}
};


int main(void)
{
	Account myAcc("56789-827120", 5000);

	try 
	{
		myAcc.Deposit(2000);
		myAcc.Deposit(-300);
	}
	catch (DepositException &expn)  // 예외객체를 굳이 복사할 필요 없어 참조자 선언
	{
		expn.ShowExceptionReason();
	}
	myAcc.ShowMyMoney();

	try
	{
		myAcc.Withdraw(3500);
		myAcc.Withdraw(4500);
	}
	catch (WithdrawExcption &expn)
	{
		expn.ShowExceptionReason();
	}
	myAcc.ShowMyMoney();

	return 0;
}
```

#### 상속관계에 있는 예외 클래스
```c++
#include <iostream>
#include <cstring>
using namespace std;

class AccountException
{
public:
	virtual void ShowExceptionReason() = 0; // 순수 가상함수
};
class DepositException : public AccountException
{
private:
	int reqDep; // 요청 입금액
public:
	DepositException(int money):reqDep(money)
	{}
	void ShowExceptionReason()
	{
		cout << "[예외 메시지: " << reqDep << "는 입금불가]" << endl;
	}
};

class WithdrawExcption : public AccountException
{
private:
	int balance; //잔고
public:
	WithdrawExcption(int money):balance(money)
	{}
	void ShowExceptionReason()
	{
		cout << "[예외 메시지: 잔액 " << balance << ", 잔액부족]" << endl;
	}
};

class Account
{
private:
	char accNum[50]; // 계좌번호
	int balance; //잔고
public:
	Account(const char * acc, int money) :balance(money)
	{
		strcpy(accNum, acc);
	}
	void Deposit(int money) throw (AccountException)
	{
		if (money < 0)
		{
			DepositException expn(money);
			throw expn;
		} 
		balance += money;
	}
	void Withdraw(int money) throw (AccountException)
	{
		if (money > balance)
			throw WithdrawExcption(balance);  // 예외객체를 전달하는 일반적인 방법
		balance -= money;
	}
	void ShowMyMoney()
	{
		cout << "잔고: " << balance << endl << endl;
	}
};


int main(void)
{
	Account myAcc("56789-827120", 5000);

	try 
	{
		myAcc.Deposit(2000);
		myAcc.Deposit(-300);
	}
	catch (AccountException &expn)  // 상속관계로 묶여있기 때문에 AccountExcpetion으로 한번에 처리 가능
	{
		expn.ShowExceptionReason();
	}
	myAcc.ShowMyMoney();

	try
	{
		myAcc.Withdraw(3500);
		myAcc.Withdraw(4500);
	}
	catch (AccountException &expn)
	{
		expn.ShowExceptionReason();
	}
	myAcc.ShowMyMoney();

	return 0;
}
```


#### 예외의 전달방식에 따른 주의사항
- 특히 상속일 때 주의! 

- 첫번째꺼는 AAA를 반환. 
- 두번째꺼는 CCC를 반환.
```C++
#include <iostream>
using namespace std;

class AAA
{
public:
	void ShowYou() { cout << "AAA expcetion!" << endl; }
};

class BBB : public AAA
{
public:
	void ShowYou() { cout << "BBB expcetion!" << endl; }
};

class CCC : public BBB
{
public:
	void ShowYou() { cout << "CCC expcetion!" << endl; }
};

void ExceptionGenerator(int expn)
{
	if (expn == 1)
		throw AAA();
	else if (expn == 2)
		throw BBB();
	else
		throw CCC();
}

int main(void)
{
	try 
	{
		ExceptionGenerator(3);
		ExceptionGenerator(2);
		ExceptionGenerator(1);
	}
	catch (AAA &expn)  
	{
		cout << "catch(AAA& expn)" << endl;
		expn.ShowYou();
	}
	catch (BBB & expn)
	{
		cout << "catch(BBB& expn)" << endl;
		expn.ShowYou();
	}
	catch (CCC & expn)
	{
		cout << "catch(CCC& expn)" << endl;
		expn.ShowYou();
	}
	

	return 0;
}
```
```C++
#include <iostream>
using namespace std;

class AAA
{
public:
	void ShowYou() { cout << "AAA expcetion!" << endl; }
};

class BBB : public AAA
{
public:
	void ShowYou() { cout << "BBB expcetion!" << endl; }
};

class CCC : public BBB
{
public:
	void ShowYou() { cout << "CCC expcetion!" << endl; }
};

void ExceptionGenerator(int expn)
{
	if (expn == 1)
		throw AAA();
	else if (expn == 2)
		throw BBB();
	else
		throw CCC();
}

int main(void)
{
	try 
	{
		ExceptionGenerator(3);
		ExceptionGenerator(2);
		ExceptionGenerator(1);
	}
	catch (CCC &expn)  
	{
		cout << "catch(CCC& expn)" << endl;
		expn.ShowYou();
	}
	catch (BBB & expn)
	{
		cout << "catch(BBB& expn)" << endl;
		expn.ShowYou();
	}
	catch (AAA & expn)
	{
		cout << "catch(AAA& expn)" << endl;
		expn.ShowYou();
	}
	

	return 0;
}
```

### 15-5. 예외처리와 관련된 또 다른 특성들
#### new 연산자에 의해서 발생하는 예외
```C++
#include <iostream>
#include <new>
using namespace std;

int main(void)
{
	int num = 0;

	try 
	{
		while (1)
		{
			num++;
			cout << num << "번째 할당시도" << endl;
			new int[10000][10000];
		}
	}
	catch (bad_alloc & bad)
	{
		cout << bad.what() << endl;  // 예외의 원인정보를 문자열의 형태로 반환
		cout << "더 이상 할당 불가";
	}
	

	return 0;
}
```

#### 모든 예외를 처리하는 catch 블록
```c++
try 
{...}
catch(...) // ...은 전달되는 모든 예외를 다 받아주겠다는 선언
{...}
```

#### 예외 던지기
- catch 블록에 전달된 예외는 다시 전달될 수 있음
```C++
#include <iostream>
using namespace std;

void Divide(int num1, int num2)
{
	try
	{
		if (num2 == 0)
			throw 0;
		cout << "몫: " << num1 / num2 << endl;
		cout << "나머지: " << num1 % num2 << endl;
	}
	catch(int expn)
	{
		cout << "first catch" << endl;
		throw; // 예외를 다시 던진다!
	}
}
int main(void)
{
	try 
	{
		Divide(9, 2);
		Divide(4, 0);
	}
	catch (int expn)
	{
		cout << "second catch" << endl;
	}
	return 0;
}
```
