### 15-1. 예외상황과 예외처리의 이해

#### 예외처리를 하지 않았을 때
```C++
#include <iostream>
using namespace std;

int main(void)
{
	int num1, num2;
	cout << "두 개의 숫자 입력: ";
	cin >> num1 >> num2;

	cout << "나눗셈의 몫: " << num1 / num2 << endl;
	cout << "나눗셈의 나머지: " << num1 % num2 << endl;
	return 0;
}
```

#### if문을 이용한 예외의 처리
- 단점 : 예외처리를 위한 코드와 프로그램의 흐름을 구성하는 코드를 쉽게 구분하지 못한다.
```C++
#include <iostream>
using namespace std;

int main(void)
{
	int num1, num2;
	cout << "두 개의 숫자 입력: ";
	cin >> num1 >> num2;

	if (num2 == 0)
	{
		cout << "제수는 0이 될 수 없습니다." << endl;
		cout << "프로그램을 다시 실행하세요." << endl;
	}
	else
	{
		cout << "나눗셈의 몫: " << num1 / num2 << endl;
		cout << "나눗셈의 나머지: " << num1 % num2 << endl;
	}
	
	return 0;
}
```

### 15-2. 예외상황과 예외처리의 이해
- try : 예외 발생에 대한 검사의 범위를 지정 
- catch : 예외처리 코드의 삽입
- throw : 예외가 발생했음을 알리는 문장의 구상에 사용

try 다음에 catch가 나오며, try 블록에서 발생한 예외는 catch 블록에서 처리됨.

```C++
#include <iostream>
using namespace std;

int main(void)
{
	int num1, num2;
	cout << "두 개의 숫자 입력: ";
	cin >> num1 >> num2;

	try
	{
		if (num2 == 0)
			throw num2;
		cout << "나눗셈의 몫: " << num1 / num2 << endl;
		cout << "나눗셈의 나머지: " << num1 % num2 << endl;
	}
	catch(int expn)  //예외가 발생하면 num2의 값으로 expn이 초기화됨
	{
		cout << "제수는 0이 될 수 없습니다." << endl;
		cout << "프로그램을 다시 실행하세요." << endl;
	}
	
	cout << "end of main" << endl;
	
	return 0;
}
```
- try 블록을 만나면 그 안에 삽입된 문장이 순서대로 실행된다.
- try 블록 내에서 예외가 발생하지 않으면 catch 블록 이후를 실행한다.
- try 블록 내에서 예외가 발생하면, 예외가 발생한 지점 이후의 나머지 try 영역을 건너 뛴다.


### 15-3. Stack Unwinding(스택 풀기)
- throw 절에 의해 예외가 발생했는데 처리하지 않앗을 때 생기는 문제
